<?xml version='1.0'?>

<robot name="udacity_bot" xmlns:xacro="http://www.ros.org/wiki/xacro">
	<xacro:include filename="$(find udacity_bot)/urdf/marvin_bot.gazebo" />

	<link name="robot_footprint"></link>

	<joint name="robot_footprint_joint" type="fixed">
		<origin xyz="0 0 0" rpy="0 0 0" />
	    	<parent link="robot_footprint"/>
	   	<child link="chassis" />
	</joint>

	<link name="chassis">
		
		<pose>0 0 0.0 0 0 0</pose>

		<inertial>
	      		<mass value="8.0"/>
	      		<origin xyz="0.0 0 0" rpy=" 0 0 0"/>
	      		<inertia
			  ixx="0.1" ixy="0" ixz="0"
			  iyy="0.1" iyz="0"
			  izz="0.1"
	      		/>
	    	</inertial>
		
		<collision name='collision'>
	      		<origin xyz="0 0 0" rpy=" 0 0 0"/> 
		        <geometry>
				<box size=".3 .3 .6"/>
		      	</geometry>
	    	</collision>

    		<visual name='chassis_visual'>
      			<origin xyz="0 0 0" rpy=" 0 0 0"/>
      			<geometry>
        			<box size=".3 .3 .6"/>
      			</geometry>
    		</visual>

		<collision name='collision_caster'>
	      		<origin xyz="-0.28 0 -0.25" rpy=" 0 0 0"/> 
		        <geometry>
				<sphere radius="0.1"/>
		      	</geometry>
		      <surface>
			<friction>
			  <ode>
			    <mu>0</mu>
			    <mu2>0</mu2>
			    <slip1>5.0</slip1>
			    <slip2>5.0</slip2>
			  </ode>
			</friction>
		      </surface>
	    	</collision>

    		<visual name='visual_caster'>
      			<origin xyz="-0.28 0 -0.25" rpy=" 0 0 0"/>
      			<geometry>
        			<sphere radius="0.1"/>
      			</geometry>
    		</visual>

	</link>

	<link name="head">
		<pose>0 0 0 0 0 0</pose>
		<inertial>
	      		<mass value="2.0"/>
	      		<origin xyz="0.0 0 0" rpy=" 0 0 0"/>
	      		<inertia
			  ixx="0.1" ixy="0" ixz="0"
			  iyy="0.1" iyz="0"
			  izz="0.1"
	      		/>
	    	</inertial>
		
		<collision>
			<origin xyz="0.0 0 0" rpy=" 0 0 0"/>
			<geometry>
				<sphere radius="0.15" />
			</geometry>			
		</collision>
		<visual>
			<origin xyz="0.0 0 0" rpy=" 0 0 0"/>
			<geometry>
				<sphere radius="0.15" />
			</geometry>			
		</visual>
	</link>

	<joint name="robot_head_joint" type="fixed">
		<origin xyz="0 0 0.4" rpy="0 0 0" />
	    	<parent link="chassis"/>
	   	<child link="head" />
	</joint>


	<link name="camera">
	    <pose>0 0 0 0 0 0</pose>
	    <inertial>
	       <mass value="0.1"/>
	       <origin xyz="0 0 0" rpy="0 0 0"/>
	       <inertia
		 ixx="1e-6" ixy="0" ixz="0"
		 iyy="1e-6" iyz="0"
		 izz="1e-6"
		/>
	    </inertial>

	    <collision>
	       <origin xyz="0 0 0" rpy="0 0 0"/>
	       <geometry>
		  <box size="0.05 0.05 0.05" />
	       </geometry>
	    </collision>

	    <visual>
	       <origin xyz="0 0 0" rpy="0 0 0"/>
	       <geometry>
		  <box size="0.05 0.05 0.05" />
	       </geometry>
	    </visual>
  	</link>

	<joint type="fixed" name="camera_joint">
	    <origin xyz="0.15 0 -0.05" rpy="0.0 0.5 0"/>
	    <child link="camera"/>
	    <parent link="head"/>
	    <axis xyz="0 1 0" rpy="0 0 0"/>
	    <limit effort="10000" velocity="1000"/>
	    <joint_properties damping="1.0" friction="1.0"/>
	</joint>

	  <link name="hokuyo">
	    <pose>0 0 0 0 0 0</pose>
	    <inertial>
	       <mass value="0.1"/>
	       <origin xyz="0 0 0" rpy="0 0 0"/>
	       <inertia
		 ixx="1e-6" ixy="0" ixz="0"
		 iyy="1e-6" iyz="0"
		 izz="1e-6"
		/>
	    </inertial>

	    <collision>
	       <origin xyz="0 0 0" rpy="0 0 0"/>
	       <geometry>
		  <box size="0.1 0.1 0.1" />
	       </geometry>
	    </collision>

	    <visual>
	       <origin xyz="0 0 0" rpy="0 0 0"/>
	       <geometry>
		  <mesh filename="package://udacity_bot/meshes/hokuyo.dae"/>
	       </geometry>
	    </visual>
	  </link>

	  <joint type="fixed" name="hokuyo_joint">
	    <origin xyz="0.15 0 0.05" rpy="0 0.1 0"/>
	    <child link="hokuyo"/>
	    <parent link="head"/>
	    <axis xyz="0 1 0" rpy="0 0 0"/>
	    <limit effort="10000" velocity="1000"/>
	    <joint_properties damping="1.0" friction="1.0"/>
	  </joint>


  <link name="left_wheel">
    <pose>0 0 0 0 1.5707 1.5707</pose>

    <inertial>
       <mass value="5.0"/>
          <origin xyz="0 0 0" rpy="0 1.5707 1.5707"/>
	     <inertia
		  ixx="0.1" ixy="0" ixz="0"
		  iyy="0.1" iyz="0"
		  izz="0.1"
	      />
    </inertial>

    <collision>
       <origin xyz="0 0 0" rpy="0 1.5707 1.5707" />
       <geometry>
          <cylinder radius="0.1" length="0.05" />
       </geometry>
    </collision>

    <visual>
       <origin xyz="0 0 0" rpy="0 1.5707 1.5707" />
       <geometry>
          <cylinder radius="0.1" length="0.1" />
       </geometry>
    </visual>

  </link>

  <joint type="continuous" name="left_wheel_hinge">
    <origin xyz="0 0.25 -0.25" rpy="0 0 0"/>
    <child link="left_wheel"/>
    <parent link="chassis"/>
    <axis xyz="0 1 0" rpy="0 0 0"/>
    <limit effort="100000" velocity="10000"/>
    <joint_properties damping="1.0" friction="1.0"/>
  </joint>


  <link name="right_wheel">
    <pose>0 0 0 0 1.5707 1.5707</pose>

    <inertial>
       <mass value="5.0"/>
          <origin xyz="0 0 0" rpy="0 1.5707 1.5707"/>
	     <inertia
		  ixx="0.1" ixy="0" ixz="0"
		  iyy="0.1" iyz="0"
		  izz="0.1"
	      />
    </inertial>

    <collision>
       <origin xyz="0 0 0" rpy="0 1.5707 1.5707" />
       <geometry>
          <cylinder radius="0.2" length="0.1" />
       </geometry>
    </collision>

    <visual>
       <origin xyz="0 0 0" rpy="0 1.5707 1.5707" />
       <geometry>
          <cylinder radius="0.1" length="0.1" />
       </geometry>
    </visual>

  </link>

  <joint type="continuous" name="right_wheel_hinge">
    <origin xyz="0 -0.25 -0.25" rpy="0 0 0"/>
    <child link="right_wheel"/>
    <parent link="chassis"/>
    <axis xyz="0 1 0" rpy="0 0 0"/>
    <limit effort="100000" velocity="10000"/>
    <joint_properties damping="1.0" friction="1.0"/>
  </joint>


	<link name="stabilizer">
		<pose>0 0 0.0 0 0 0</pose>

		<inertial>
	      		<mass value="0.2"/>
	      		<origin xyz="0.0 0 0" rpy=" 0 0 0"/>
	      		<inertia
			 ixx="1e-6" ixy="0" ixz="0"
			 iyy="1e-6" iyz="0"
			 izz="1e-6"
			/>
	    	</inertial>
		
		<collision name='collision'>
	      		<origin xyz="0 0 0" rpy=" 0 0 0"/> 
		        <geometry>
				<sphere radius="0.05"/>
		      	</geometry>
	    	</collision>

    		<visual name='chassis_visual'>
      			<origin xyz="0 0 0" rpy=" 0 0 0"/>
      			<geometry>
        			<sphere radius="0.05"/>
      			</geometry>
    		</visual>
			
	</link>

	<joint name="stabilizer_joint" type="fixed">
		<origin xyz="-0.19 0 0.4" rpy="0 0 0" />
	    	<parent link="chassis"/>
	   	<child link="stabilizer" />
	</joint>
	

</robot>
